Workbook

Sheet Summary
A1: Modern Edge® Tactical v3.3 — Live Paper Track Record
A2: Auto-computed from Sheet1.
A3: Record from the 8/3/2026 close (v3.3 inception); the account was funded 7/27 under v3.1. Positions, closes and cash rebuilt from Alpaca 10/3/2026: account value matches Alpaca daily equity to the cent.
A4: Live
A5: Start date | B5: =Sheet1!A3
A6: Latest date | B6: =INDEX(Sheet1!$A$3:$A$385,COUNT(Sheet1!$B$3:$B$387))
A7: Trading days logged | B7: =COUNT(Sheet1!$B$3:$B$387)
A8: Starting value | B8: =Sheet1!$B$3
A9: Current value | B9: =INDEX(Sheet1!$B$3:$B$387,COUNT(Sheet1!$B$3:$B$387))
A10: Cumulative return | B10: =INDEX(Sheet1!$B$3:$B$387,COUNT(Sheet1!$B$3:$B$387))/Sheet1!$B$3-1
A11: Annualized (CAGR) | B11: =(INDEX(Sheet1!$B$3:$B$387,COUNT(Sheet1!$B$3:$B$387))/Sheet1!$B$3)^(252/COUNT(Sheet1!$B$3:$B$387))-1
A12: Annualized volatility | B12: =STDEV(Sheet1!$V$4:$V$387)*SQRT(252)
A13: Sharpe (rf=0) | B13: =IFERROR(AVERAGE(Sheet1!$V$4:$V$387)*252/(STDEV(Sheet1!$V$4:$V$387)*SQRT(252)),"")
A14: Max drawdown | B14: =MIN(Sheet1!$Y$3:$Y$387)
A15: Current drawdown | B15: =INDEX(Sheet1!$Y$3:$Y$387,COUNT(Sheet1!$B$3:$B$387))
A16: Best day | B16: =MAX(Sheet1!$V$4:$V$387)
A17: Worst day | B17: =MIN(Sheet1!$V$4:$V$387)
A18: % up days | B18: =IFERROR(COUNTIF(Sheet1!$V$4:$V$387,">0")/COUNT(Sheet1!$V$4:$V$387),"")
A19: Time in cash (lev < 0.1x) | B19: =IFERROR(COUNTIF(Sheet1!$K$3:$K$387,"<0.1")/COUNT(Sheet1!$B$3:$B$387),"")
A20: Excess vs buy & hold QQQ | B20: =INDEX(Sheet1!$AB$3:$AB$387,COUNT(Sheet1!$B$3:$B$387))
A22: Backtest reference (1986–2026, hypothetical)
A23: Annualized (CAGR) | B23: 0.206
A24: Sharpe | B24: 0.83
A25: Max drawdown | B25: -0.31
A27: Legend — Sheet1 inputs you fill (amber): SGOV shares/price, cash, reported equity, traded?, emergency day, notes. Everything else auto-computes. To add a day, copy the last data row down.

Sheet Sheet1
A1: Modern Edge® Tactical v3.3 | B1: Portfolio values | L1: recommendations as of previous close | N1: Daily trend Monitor | O1: Monitor values as of previous close | U1: Emergency Exit | V1: Performance | Z1: Benchmark · buy & hold QQQ | AC1: Cash sleeve (SGOV) — fill when in cash
B2: acct value | C2: shares | D2: close price | E2: qqq | G2: shares | H2: close price | I2: tqqq | K2: live leverage | L2: daily rec | M2: live recommendation | N2: leverage tv wants | O2: daily v | P2: daily t | Q2: previous month V | R2: previous month t | S2: price vs 200ma | U2: Triggered | V2: daily return | W2: cumulative return | X2: peak equity | Y2: drawdown | Z2: QQQ B&H equity | AA2: QQQ cum return | AB2: excess vs QQQ | AC2: SGOV shares | AD2: SGOV price | AE2: SGOV value | AF2: SGOV weight | AG2: cash | AH2: traded? (Y/N) | AI2: emergency day | AJ2: notes
A3: 46237 | B3: =IF(AND(E3="",I3="",AE3="",AG3=""),"",SUM(E3,I3,AE3,AG3)) | C3: 146.89422 | D3: 700.07 | E3: =IF(D3="","",D3*C3) | F3: =E3/B3 | G3: 0 | H3: 67.96 | I3: =IF(H3="","",H3*G3) | J3: =I3/B3 | K3: =F3+J3*3 | L3: 1.05x | M3: no change - hold current position | N3: 1.08x | O3: 0.89 | P3: 0.36 | Q3: 0.92 | R3: 0.17 | S3: 80 | T3: above | U3: No | W3: =IF(B3="","",B3/$B$3-1) | X3: =IF(B3="","",MAX($B$3:B3)) | Y3: =IF(OR(B3="",X3=""),"",B3/X3-1) | Z3: =IF(D3="","",$B$3*D3/$D$3) | AA3: =IF(D3="","",D3/$D$3-1) | AB3: =IF(OR(W3="",AA3=""),"",W3-AA3) | AE3: =IF(AD3="","",AC3*AD3) | AF3: =IF(OR(AE3="",B3="",B3=0),"",AE3/B3) | AG3: 0 | AJ3: v3.3 record starts at this close (v3.2/v3.3 created 8/3). Account was funded 7/27 under v3.1: $100,000 into 146.894 QQQ (1.00x). No trades 8/3-8/17: 1.00x vs the 1.05x target is inside the 0.10 rebalance band.
A4: 46238 | B4: =IF(AND(E4="",I4="",AE4="",AG4=""),"",SUM(E4,I4,AE4,AG4)) | C4: 146.89422 | D4: 723.85 | E4: =IF(D4="","",D4*C4) | F4: =E4/B4 | G4: 0 | H4: 74.82 | I4: =IF(H4="","",H4*G4) | J4: =I4/B4 | K4: =F4+J4*3 | L4: 1.05x | M4: no change - hold current position | N4: 1.06x | O4: 0.89 | P4: 0.34 | Q4: 0.92 | R4: 0.17 | S4: 81 | T4: above | U4: No | V4: =IF(OR(B4="",B3=""),"",B4/B3-1) | W4: =IF(B4="","",B4/$B$3-1) | X4: =IF(B4="","",MAX($B$3:B4)) | Y4: =IF(OR(B4="",X4=""),"",B4/X4-1) | Z4: =IF(D4="","",$B$3*D4/$D$3) | AA4: =IF(D4="","",D4/$D$3-1) | AB4: =IF(OR(W4="",AA4=""),"",W4-AA4) | AE4: =IF(AD4="","",AC4*AD4) | AF4: =IF(OR(AE4="",B4="",B4=0),"",AE4/B4) | AG4: 0
A5: 46239 | B5: =IF(AND(E5="",I5="",AE5="",AG5=""),"",SUM(E5,I5,AE5,AG5)) | C5: 146.89422 | D5: 717.3 | E5: =IF(D5="","",D5*C5) | F5: =E5/B5 | G5: 0 | H5: 72.84 | I5: =IF(H5="","",H5*G5) | J5: =I5/B5 | K5: =F5+J5*3 | L5: 1.05x | M5: no change - hold current position | N5: 0.98x | O5: 0.89 | P5: 0.3 | Q5: 0.92 | R5: 0.17 | S5: 82 | T5: above | U5: No | V5: =IF(OR(B5="",B4=""),"",B5/B4-1) | W5: =IF(B5="","",B5/$B$3-1) | X5: =IF(B5="","",MAX($B$3:B5)) | Y5: =IF(OR(B5="",X5=""),"",B5/X5-1) | Z5: =IF(D5="","",$B$3*D5/$D$3) | AA5: =IF(D5="","",D5/$D$3-1) | AB5: =IF(OR(W5="",AA5=""),"",W5-AA5) | AE5: =IF(AD5="","",AC5*AD5) | AF5: =IF(OR(AE5="",B5="",B5=0),"",AE5/B5) | AG5: 0
A6: 46240 | B6: =IF(AND(E6="",I6="",AE6="",AG6=""),"",SUM(E6,I6,AE6,AG6)) | C6: 146.89422 | D6: 714.65 | E6: =IF(D6="","",D6*C6) | F6: =IF(B6="","",E6/B6) | G6: 0 | H6: 72.03 | I6: =IF(H6="","",H6*G6) | J6: =IF(B6="","",I6/B6) | K6: =IF(B6="","",F6+J6*3) | L6: 1.05x | M6: no change - hold current position | N6: 0.97x | O6: 0.89 | P6: 0.32 | Q6: 0.92 | R6: 0.17 | S6: 83 | T6: above | U6: No | V6: =IF(OR(B6="",B5=""),"",B6/B5-1) | W6: =IF(B6="","",B6/$B$3-1) | X6: =IF(B6="","",MAX($B$3:B6)) | Y6: =IF(OR(B6="",X6=""),"",B6/X6-1) | Z6: =IF(D6="","",$B$3*D6/$D$3) | AA6: =IF(D6="","",D6/$D$3-1) | AB6: =IF(OR(W6="",AA6=""),"",W6-AA6) | AE6: =IF(AD6="","",AC6*AD6) | AF6: =IF(OR(AE6="",B6="",B6=0),"",AE6/B6) | AG6: 0
A7: 46241 | B7: =IF(AND(E7="",I7="",AE7="",AG7=""),"",SUM(E7,I7,AE7,AG7)) | C7: 146.89422 | D7: 723.03 | E7: =IF(D7="","",D7*C7) | F7: =IF(B7="","",E7/B7) | G7: 0 | H7: 74.47 | I7: =IF(H7="","",H7*G7) | J7: =IF(B7="","",I7/B7) | K7: =IF(B7="","",F7+J7*3) | L7: 1.05x | M7: no change - hold current position | N7: 1.00x | O7: 0.89 | P7: 0.32 | Q7: 0.92 | R7: 0.17 | S7: 84 | T7: above | U7: No | V7: =IF(OR(B7="",B6=""),"",B7/B6-1) | W7: =IF(B7="","",B7/$B$3-1) | X7: =IF(B7="","",MAX($B$3:B7)) | Y7: =IF(OR(B7="",X7=""),"",B7/X7-1) | Z7: =IF(D7="","",$B$3*D7/$D$3) | AA7: =IF(D7="","",D7/$D$3-1) | AB7: =IF(OR(W7="",AA7=""),"",W7-AA7) | AE7: =IF(AD7="","",AC7*AD7) | AF7: =IF(OR(AE7="",B7="",B7=0),"",AE7/B7) | AG7: 0
A8: 46244 | B8: =IF(AND(E8="",I8="",AE8="",AG8=""),"",SUM(E8,I8,AE8,AG8)) | C8: 146.89422 | D8: 720.87 | E8: =IF(D8="","",D8*C8) | F8: =IF(B8="","",E8/B8) | G8: 0 | H8: 73.8 | I8: =IF(H8="","",H8*G8) | J8: =IF(B8="","",I8/B8) | K8: =IF(B8="","",F8+J8*3) | L8: 1.05x | M8: no change - hold current position | N8: 0.98x | O8: 0.89 | P8: 0.34 | Q8: 0.92 | R8: 0.17 | S8: 85 | T8: above | U8: No | V8: =IF(OR(B8="",B7=""),"",B8/B7-1) | W8: =IF(B8="","",B8/$B$3-1) | X8: =IF(B8="","",MAX($B$3:B8)) | Y8: =IF(OR(B8="",X8=""),"",B8/X8-1) | Z8: =IF(D8="","",$B$3*D8/$D$3) | AA8: =IF(D8="","",D8/$D$3-1) | AB8: =IF(OR(W8="",AA8=""),"",W8-AA8) | AE8: =IF(AD8="","",AC8*AD8) | AF8: =IF(OR(AE8="",B8="",B8=0),"",AE8/B8) | AG8: 0
A9: 46245 | B9: =IF(AND(E9="",I9="",AE9="",AG9=""),"",SUM(E9,I9,AE9,AG9)) | C9: 146.89422 | D9: 718.45 | E9: =IF(D9="","",D9*C9) | F9: =IF(B9="","",E9/B9) | G9: 0 | H9: 73.06 | I9: =IF(H9="","",H9*G9) | J9: =IF(B9="","",I9/B9) | K9: =IF(B9="","",F9+J9*3) | L9: 1.05x | M9: no change - hold current position | N9: 1.02x | O9: 0.89 | P9: 0.36 | Q9: 0.92 | R9: 0.17 | S9: 86 | T9: above | U9: No | V9: =IF(OR(B9="",B8=""),"",B9/B8-1) | W9: =IF(B9="","",B9/$B$3-1) | X9: =IF(B9="","",MAX($B$3:B9)) | Y9: =IF(OR(B9="",X9=""),"",B9/X9-1) | Z9: =IF(D9="","",$B$3*D9/$D$3) | AA9: =IF(D9="","",D9/$D$3-1) | AB9: =IF(OR(W9="",AA9=""),"",W9-AA9) | AE9: =IF(AD9="","",AC9*AD9) | AF9: =IF(OR(AE9="",B9="",B9=0),"",AE9/B9) | AG9: 0
A10: 46246 | B10: =IF(AND(E10="",I10="",AE10="",AG10=""),"",SUM(E10,I10,AE10,AG10)) | C10: 146.89422 | D10: 723.7 | E10: =IF(D10="","",D10*C10) | F10: =IF(B10="","",E10/B10) | G10: 0 | H10: 74.6 | I10: =IF(H10="","",H10*G10) | J10: =IF(B10="","",I10/B10) | K10: =IF(B10="","",F10+J10*3) | L10: 1.05x | M10: no change - hold current position | N10: 1.03x | O10: 0.89 | P10: 0.37 | Q10: 0.92 | R10: 0.17 | S10: 87 | T10: above | U10: No | V10: =IF(OR(B10="",B9=""),"",B10/B9-1) | W10: =IF(B10="","",B10/$B$3-1) | X10: =IF(B10="","",MAX($B$3:B10)) | Y10: =IF(OR(B10="",X10=""),"",B10/X10-1) | Z10: =IF(D10="","",$B$3*D10/$D$3) | AA10: =IF(D10="","",D10/$D$3-1) | AB10: =IF(OR(W10="",AA10=""),"",W10-AA10) | AE10: =IF(AD10="","",AC10*AD10) | AF10: =IF(OR(AE10="",B10="",B10=0),"",AE10/B10) | AG10: 0
A11: 46247 | B11: =IF(AND(E11="",I11="",AE11="",AG11=""),"",SUM(E11,I11,AE11,AG11)) | C11: 146.89422 | D11: 732.07 | E11: =IF(D11="","",D11*C11) | F11: =IF(B11="","",E11/B11) | G11: 0 | H11: 77.15 | I11: =IF(H11="","",H11*G11) | J11: =IF(B11="","",I11/B11) | K11: =IF(B11="","",F11+J11*3) | L11: 1.05x | M11: no change - hold current position | N11: 1.02x | O11: 0.89 | P11: 0.36 | Q11: 0.92 | R11: 0.17 | S11: 88 | T11: above | U11: No | V11: =IF(OR(B11="",B10=""),"",B11/B10-1) | W11: =IF(B11="","",B11/$B$3-1) | X11: =IF(B11="","",MAX($B$3:B11)) | Y11: =IF(OR(B11="",X11=""),"",B11/X11-1) | Z11: =IF(D11="","",$B$3*D11/$D$3) | AA11: =IF(D11="","",D11/$D$3-1) | AB11: =IF(OR(W11="",AA11=""),"",W11-AA11) | AE11: =IF(AD11="","",AC11*AD11) | AF11: =IF(OR(AE11="",B11="",B11=0),"",AE11/B11) | AG11: 0
A12: 46248 | B12: =IF(AND(E12="",I12="",AE12="",AG12=""),"",SUM(E12,I12,AE12,AG12)) | C12: 146.89422 | D12: 731.07 | E12: =IF(D12="","",D12*C12) | F12: =IF(B12="","",E12/B12) | G12: 0 | H12: 76.79 | I12: =IF(H12="","",H12*G12) | J12: =IF(B12="","",I12/B12) | K12: =IF(B12="","",F12+J12*3) | L12: 1.05x | M12: no change - hold current position | N12: 1.04x | O12: 0.9 | P12: 0.36 | Q12: 0.92 | R12: 0.17 | S12: 89 | T12: above | U12: No | V12: =IF(OR(B12="",B11=""),"",B12/B11-1) | W12: =IF(B12="","",B12/$B$3-1) | X12: =IF(B12="","",MAX($B$3:B12)) | Y12: =IF(OR(B12="",X12=""),"",B12/X12-1) | Z12: =IF(D12="","",$B$3*D12/$D$3) | AA12: =IF(D12="","",D12/$D$3-1) | AB12: =IF(OR(W12="",AA12=""),"",W12-AA12) | AE12: =IF(AD12="","",AC12*AD12) | AF12: =IF(OR(AE12="",B12="",B12=0),"",AE12/B12) | AG12: 0
A13: 46251 | B13: =IF(AND(E13="",I13="",AE13="",AG13=""),"",SUM(E13,I13,AE13,AG13)) | C13: 146.89422 | D13: 729.87 | E13: =IF(D13="","",D13*C13) | F13: =IF(B13="","",E13/B13) | G13: 0 | H13: 76.4 | I13: =IF(H13="","",H13*G13) | J13: =IF(B13="","",I13/B13) | K13: =IF(B13="","",F13+J13*3) | L13: 1.05x | M13: no change - hold current position | N13: 1.07x | O13: 0.9 | P13: 0.38 | Q13: 0.92 | R13: 0.17 | S13: 90 | T13: above | U13: No | V13: =IF(OR(B13="",B12=""),"",B13/B12-1) | W13: =IF(B13="","",B13/$B$3-1) | X13: =IF(B13="","",MAX($B$3:B13)) | Y13: =IF(OR(B13="",X13=""),"",B13/X13-1) | Z13: =IF(D13="","",$B$3*D13/$D$3) | AA13: =IF(D13="","",D13/$D$3-1) | AB13: =IF(OR(W13="",AA13=""),"",W13-AA13) | AE13: =IF(AD13="","",AC13*AD13) | AF13: =IF(OR(AE13="",B13="",B13=0),"",AE13/B13) | AG13: 0
A14: 46252 | B14: =IF(AND(E14="",I14="",AE14="",AG14=""),"",SUM(E14,I14,AE14,AG14)) | C14: 142.9799 | D14: 717.51 | E14: =IF(D14="","",D14*C14) | F14: =IF(B14="","",E14/B14) | G14: 37.394546 | H14: 72.53 | I14: =IF(H14="","",H14*G14) | J14: =IF(B14="","",I14/B14) | K14: =IF(B14="","",F14+J14*3) | L14: 1.05x | M14: no change - hold current position | N14: 1.07x | O14: 0.89 | P14: 0.37 | Q14: 0.92 | R14: 0.17 | S14: 91 | T14: above | U14: No | V14: =IF(OR(B14="",B13=""),"",B14/B13-1) | W14: =IF(B14="","",B14/$B$3-1) | X14: =IF(B14="","",MAX($B$3:B14)) | Y14: =IF(OR(B14="",X14=""),"",B14/X14-1) | Z14: =IF(D14="","",$B$3*D14/$D$3) | AA14: =IF(D14="","",D14/$D$3-1) | AB14: =IF(OR(W14="",AA14=""),"",W14-AA14) | AE14: =IF(AD14="","",AC14*AD14) | AF14: =IF(OR(AE14="",B14="",B14=0),"",AE14/B14) | AG14: 76.11 | AH14: Y | AJ14: First TQQQ purchase (1.00x -> ~1.05x). Pre-market share-quantity orders (later rebalances are dollar orders sent after the open). Missing from the original log; added from Alpaca.
A15: 46253 | B15: =IF(AND(E15="",I15="",AE15="",AG15=""),"",SUM(E15,I15,AE15,AG15)) | C15: 142.9799 | D15: 716.08 | E15: =IF(D15="","",D15*C15) | F15: =IF(B15="","",E15/B15) | G15: 37.394546 | H15: 72.06 | I15: =IF(H15="","",H15*G15) | J15: =IF(B15="","",I15/B15) | K15: =IF(B15="","",F15+J15*3) | L15: 1.05x | M15: no change - hold current position | N15: 1.08x | O15: 0.89 | P15: 0.39 | Q15: 0.92 | R15: 0.17 | S15: 92 | T15: above | U15: No | V15: =IF(OR(B15="",B14=""),"",B15/B14-1) | W15: =IF(B15="","",B15/$B$3-1) | X15: =IF(B15="","",MAX($B$3:B15)) | Y15: =IF(OR(B15="",X15=""),"",B15/X15-1) | Z15: =IF(D15="","",$B$3*D15/$D$3) | AA15: =IF(D15="","",D15/$D$3-1) | AB15: =IF(OR(W15="",AA15=""),"",W15-AA15) | AE15: =IF(AD15="","",AC15*AD15) | AF15: =IF(OR(AE15="",B15="",B15=0),"",AE15/B15) | AG15: 76.11
A16: 46254 | B16: =IF(AND(E16="",I16="",AE16="",AG16=""),"",SUM(E16,I16,AE16,AG16)) | C16: 142.9799 | D16: 710.93 | E16: =IF(D16="","",D16*C16) | F16: =IF(B16="","",E16/B16) | G16: 37.394546 | H16: 70.48 | I16: =IF(H16="","",H16*G16) | J16: =IF(B16="","",I16/B16) | K16: =IF(B16="","",F16+J16*3) | L16: 1.05x | M16: no change - hold current position | N16: 1.08x | O16: 0.89 | P16: 0.4 | Q16: 0.92 | R16: 0.17 | S16: 93 | T16: above | U16: No | V16: =IF(OR(B16="",B15=""),"",B16/B15-1) | W16: =IF(B16="","",B16/$B$3-1) | X16: =IF(B16="","",MAX($B$3:B16)) | Y16: =IF(OR(B16="",X16=""),"",B16/X16-1) | Z16: =IF(D16="","",$B$3*D16/$D$3) | AA16: =IF(D16="","",D16/$D$3-1) | AB16: =IF(OR(W16="",AA16=""),"",W16-AA16) | AE16: =IF(AD16="","",AC16*AD16) | AF16: =IF(OR(AE16="",B16="",B16=0),"",AE16/B16) | AG16: 76.11
A17: 46255 | B17: =IF(AND(E17="",I17="",AE17="",AG17=""),"",SUM(E17,I17,AE17,AG17)) | C17: 142.9799 | D17: 713.44 | E17: =IF(D17="","",D17*C17) | F17: =IF(B17="","",E17/B17) | G17: 37.394546 | H17: 71.17 | I17: =IF(H17="","",H17*G17) | J17: =IF(B17="","",I17/B17) | K17: =IF(B17="","",F17+J17*3) | L17: 1.05x | M17: no change - hold current position | N17: 1.12x | O17: 0.89 | P17: 0.4 | Q17: 0.92 | R17: 0.17 | S17: 94 | T17: above | U17: No | V17: =IF(OR(B17="",B16=""),"",B17/B16-1) | W17: =IF(B17="","",B17/$B$3-1) | X17: =IF(B17="","",MAX($B$3:B17)) | Y17: =IF(OR(B17="",X17=""),"",B17/X17-1) | Z17: =IF(D17="","",$B$3*D17/$D$3) | AA17: =IF(D17="","",D17/$D$3-1) | AB17: =IF(OR(W17="",AA17=""),"",W17-AA17) | AE17: =IF(AD17="","",AC17*AD17) | AF17: =IF(OR(AE17="",B17="",B17=0),"",AE17/B17) | AG17: 76.11
A18: 46258 | B18: =IF(AND(E18="",I18="",AE18="",AG18=""),"",SUM(E18,I18,AE18,AG18)) | C18: 142.9799 | D18: 706.32 | E18: =IF(D18="","",D18*C18) | F18: =IF(B18="","",E18/B18) | G18: 37.394546 | H18: 69.01 | I18: =IF(H18="","",H18*G18) | J18: =IF(B18="","",I18/B18) | K18: =IF(B18="","",F18+J18*3) | L18: 1.05x | M18: no change - hold current position | N18: 1.14x | O18: 0.89 | P18: 0.42 | Q18: 0.92 | R18: 0.17 | S18: 95 | T18: above | U18: No | V18: =IF(OR(B18="",B17=""),"",B18/B17-1) | W18: =IF(B18="","",B18/$B$3-1) | X18: =IF(B18="","",MAX($B$3:B18)) | Y18: =IF(OR(B18="",X18=""),"",B18/X18-1) | Z18: =IF(D18="","",$B$3*D18/$D$3) | AA18: =IF(D18="","",D18/$D$3-1) | AB18: =IF(OR(W18="",AA18=""),"",W18-AA18) | AE18: =IF(AD18="","",AC18*AD18) | AF18: =IF(OR(AE18="",B18="",B18=0),"",AE18/B18) | AG18: 76.11
A19: 46259 | B19: =IF(AND(E19="",I19="",AE19="",AG19=""),"",SUM(E19,I19,AE19,AG19)) | C19: 124.13859 | D19: 710.72 | E19: =IF(D19="","",D19*C19) | F19: =IF(B19="","",E19/B19) | G19: 229.29055 | H19: 70.27 | I19: =IF(H19="","",H19*G19) | J19: =IF(B19="","",I19/B19) | K19: =IF(B19="","",F19+J19*3) | L19: 1.31x | M19: REBALANCE — 96.50% QQQ / 3.50% TQQQ → 84.53% QQQ / 15.47% TQQQ | N19: 1.38x | O19: 0.89 | P19: 0.44 | Q19: 0.92 | R19: 0.17 | S19: 96 | T19: above | U19: No | V19: =IF(OR(B19="",B18=""),"",B19/B18-1) | W19: =IF(B19="","",B19/$B$3-1) | X19: =IF(B19="","",MAX($B$3:B19)) | Y19: =IF(OR(B19="",X19=""),"",B19/X19-1) | Z19: =IF(D19="","",$B$3*D19/$D$3) | AA19: =IF(D19="","",D19/$D$3-1) | AB19: =IF(OR(W19="",AA19=""),"",W19-AA19) | AE19: =IF(AD19="","",AC19*AD19) | AF19: =IF(OR(AE19="",B19="",B19=0),"",AE19/B19) | AG19: -0.3 | AH19: Y | AJ19: BUG WAS FOUND IN THE FETCH AND BUILD PY FILE
A20: 46260 | B20: =IF(AND(E20="",I20="",AE20="",AG20=""),"",SUM(E20,I20,AE20,AG20)) | C20: 143.27018 | D20: 711.37 | E20: =IF(D20="","",D20*C20) | F20: =IF(B20="","",E20/B20) | G20: 35.686851 | H20: 70.47 | I20: =IF(H20="","",H20*G20) | J20: =IF(B20="","",I20/B20) | K20: =IF(B20="","",F20+J20*3) | L20: 1.05x | M20: REBALANCE — 84.53% QQQ / 15.47% TQQQ → 96.50% QQQ / 3.50% TQQQ | N20: 1.13x | O20: 0.89 | P20: 0.45 | Q20: 0.92 | R20: 0.17 | S20: 97 | T20: above | U20: No | V20: =IF(OR(B20="",B19=""),"",B20/B19-1) | W20: =IF(B20="","",B20/$B$3-1) | X20: =IF(B20="","",MAX($B$3:B20)) | Y20: =IF(OR(B20="",X20=""),"",B20/X20-1) | Z20: =IF(D20="","",$B$3*D20/$D$3) | AA20: =IF(D20="","",D20/$D$3-1) | AB20: =IF(OR(W20="",AA20=""),"",W20-AA20) | AE20: =IF(AD20="","",AC20*AD20) | AF20: =IF(OR(AE20="",B20="",B20=0),"",AE20/B20) | AG20: -0.64 | AH20: Y | AJ20: Adjustment back after bug fix
A21: 46261 | B21: =IF(AND(E21="",I21="",AE21="",AG21=""),"",SUM(E21,I21,AE21,AG21)) | C21: 132.0286 | D21: 721.11 | E21: =IF(D21="","",D21*C21) | F21: =IF(B21="","",E21/B21) | G21: 147.8347 | H21: 73.3 | I21: =IF(H21="","",H21*G21) | J21: =IF(B21="","",I21/B21) | K21: =IF(B21="","",F21+J21*3) | L21: 1.20x | M21: REBALANCE — 96.50% QQQ / 3.50% TQQQ → 89.91% QQQ / 10.09% TQQQ | N21: 1.20x | O21: 0.89 | P21: 0.43 | Q21: 0.92 | R21: 0.17 | S21: 98 | T21: above | U21: No | V21: =IF(OR(B21="",B20=""),"",B21/B20-1) | W21: =IF(B21="","",B21/$B$3-1) | X21: =IF(B21="","",MAX($B$3:B21)) | Y21: =IF(OR(B21="",X21=""),"",B21/X21-1) | Z21: =IF(D21="","",$B$3*D21/$D$3) | AA21: =IF(D21="","",D21/$D$3-1) | AB21: =IF(OR(W21="",AA21=""),"",W21-AA21) | AE21: =IF(AD21="","",AC21*AD21) | AF21: =IF(OR(AE21="",B21="",B21=0),"",AE21/B21) | AG21: -0.53 | AH21: Y
A22: 46262 | B22: =IF(AND(E22="",I22="",AE22="",AG22=""),"",SUM(E22,I22,AE22,AG22)) | C22: 117.82846 | D22: 716.43 | E22: =IF(D22="","",D22*C22) | F22: =IF(B22="","",E22/B22) | G22: 288.69532 | H22: 71.85 | I22: =IF(H22="","",H22*G22) | J22: =IF(B22="","",I22/B22) | K22: =IF(B22="","",F22+J22*3) | L22: 1.40x | M22: REBALANCE — 89.91% QQQ / 10.09% TQQQ → 80.17% QQQ / 19.83% TQQQ | N22: 1.40x | O22: 0.9 | P22: 0.43 | Q22: 0.92 | R22: 0.17 | S22: 99 | T22: above | U22: No | V22: =IF(OR(B22="",B21=""),"",B22/B21-1) | W22: =IF(B22="","",B22/$B$3-1) | X22: =IF(B22="","",MAX($B$3:B22)) | Y22: =IF(OR(B22="",X22=""),"",B22/X22-1) | Z22: =IF(D22="","",$B$3*D22/$D$3) | AA22: =IF(D22="","",D22/$D$3-1) | AB22: =IF(OR(W22="",AA22=""),"",W22-AA22) | AE22: =IF(AD22="","",AC22*AD22) | AF22: =IF(OR(AE22="",B22="",B22=0),"",AE22/B22) | AG22: -0.43 | AH22: Y
A23: 46265 | B23: =IF(AND(E23="",I23="",AE23="",AG23=""),"",SUM(E23,I23,AE23,AG23)) | C23: 117.82846 | D23: 716.76 | E23: =IF(D23="","",D23*C23) | F23: =IF(B23="","",E23/B23) | G23: 288.69532 | H23: 71.92 | I23: =IF(H23="","",H23*G23) | J23: =IF(B23="","",I23/B23) | K23: =IF(B23="","",F23+J23*3) | L23: 1.40x | M23: no change - hold current position | N23: 1.39x | O23: 0.9 | P23: 0.44 | Q23: 0.92 | R23: 0.17 | S23: 100 | T23: above | U23: No | V23: =IF(OR(B23="",B22=""),"",B23/B22-1) | W23: =IF(B23="","",B23/$B$3-1) | X23: =IF(B23="","",MAX($B$3:B23)) | Y23: =IF(OR(B23="",X23=""),"",B23/X23-1) | Z23: =IF(D23="","",$B$3*D23/$D$3) | AA23: =IF(D23="","",D23/$D$3-1) | AB23: =IF(OR(W23="",AA23=""),"",W23-AA23) | AE23: =IF(AD23="","",AC23*AD23) | AF23: =IF(OR(AE23="",B23="",B23=0),"",AE23/B23) | AG23: -0.43
A24: 46266 | B24: =IF(AND(E24="",I24="",AE24="",AG24=""),"",SUM(E24,I24,AE24,AG24)) | C24: 117.82846 | D24: 707.64 | E24: =IF(D24="","",D24*C24) | F24: =IF(B24="","",E24/B24) | G24: 288.69532 | H24: 69.15 | I24: =IF(H24="","",H24*G24) | J24: =IF(B24="","",I24/B24) | K24: =IF(B24="","",F24+J24*3) | L24: 1.40x | M24: no change - hold current position | N24: 1.49x | O24: 0.9 | P24: 0.44 | Q24: 0.92 | R24: 0.17 | S24: 101 | T24: above | U24: No | V24: =IF(OR(B24="",B23=""),"",B24/B23-1) | W24: =IF(B24="","",B24/$B$3-1) | X24: =IF(B24="","",MAX($B$3:B24)) | Y24: =IF(OR(B24="",X24=""),"",B24/X24-1) | Z24: =IF(D24="","",$B$3*D24/$D$3) | AA24: =IF(D24="","",D24/$D$3-1) | AB24: =IF(OR(W24="",AA24=""),"",W24-AA24) | AE24: =IF(AD24="","",AC24*AD24) | AF24: =IF(OR(AE24="",B24="",B24=0),"",AE24/B24) | AG24: -0.43
A25: 46267 | B25: =IF(AND(E25="",I25="",AE25="",AG25=""),"",SUM(E25,I25,AE25,AG25)) | C25: 117.82846 | D25: 709.24 | E25: =IF(D25="","",D25*C25) | F25: =IF(B25="","",E25/B25) | G25: 288.69532 | H25: 69.6 | I25: =IF(H25="","",H25*G25) | J25: =IF(B25="","",I25/B25) | K25: =IF(B25="","",F25+J25*3) | L25: 1.40x | M25: no change - hold current position | N25: 1.44x | O25: 0.89 | P25: 0.48 | Q25: 0.91 | R25: 0.28 | S25: 102 | T25: above | U25: No | V25: =IF(OR(B25="",B24=""),"",B25/B24-1) | W25: =IF(B25="","",B25/$B$3-1) | X25: =IF(B25="","",MAX($B$3:B25)) | Y25: =IF(OR(B25="",X25=""),"",B25/X25-1) | Z25: =IF(D25="","",$B$3*D25/$D$3) | AA25: =IF(D25="","",D25/$D$3-1) | AB25: =IF(OR(W25="",AA25=""),"",W25-AA25) | AE25: =IF(AD25="","",AC25*AD25) | AF25: =IF(OR(AE25="",B25="",B25=0),"",AE25/B25) | AG25: -0.43
A26: 46268 | B26: =IF(AND(E26="",I26="",AE26="",AG26=""),"",SUM(E26,I26,AE26,AG26)) | C26: 79.076369 | D26: 717.67 | E26: =IF(D26="","",D26*C26) | F26: =IF(B26="","",E26/B26) | G26: 682.07247 | H26: 72.03 | I26: =IF(H26="","",H26*G26) | J26: =IF(B26="","",I26/B26) | K26: =IF(B26="","",F26+J26*3) | L26: 1.92x | M26: REBALANCE — 80.17% QQQ / 19.83% TQQQ → 54.04% QQQ / 45.96% TQQQ | N26: 1.97x | O26: 0.9 | P26: 0.44 | Q26: 0.91 | R26: 0.28 | S26: 103 | T26: above | U26: No | V26: =IF(OR(B26="",B25=""),"",B26/B25-1) | W26: =IF(B26="","",B26/$B$3-1) | X26: =IF(B26="","",MAX($B$3:B26)) | Y26: =IF(OR(B26="",X26=""),"",B26/X26-1) | Z26: =IF(D26="","",$B$3*D26/$D$3) | AA26: =IF(D26="","",D26/$D$3-1) | AB26: =IF(OR(W26="",AA26=""),"",W26-AA26) | AE26: =IF(AD26="","",AC26*AD26) | AF26: =IF(OR(AE26="",B26="",B26=0),"",AE26/B26) | AG26: -0.59 | AH26: Y
A27: 46269 | B27: =IF(AND(E27="",I27="",AE27="",AG27=""),"",SUM(E27,I27,AE27,AG27)) | C27: 79.076369 | D27: 718.96 | E27: =IF(D27="","",D27*C27) | F27: =IF(B27="","",E27/B27) | G27: 682.07247 | H27: 72.37 | I27: =IF(H27="","",H27*G27) | J27: =IF(B27="","",I27/B27) | K27: =IF(B27="","",F27+J27*3) | L27: 1.92x | M27: no change - hold current position | N27: 1.88x | O27: 0.9 | P27: 0.43 | Q27: 0.91 | R27: 0.28 | S27: 104 | T27: above | U27: No | V27: =IF(OR(B27="",B26=""),"",B27/B26-1) | W27: =IF(B27="","",B27/$B$3-1) | X27: =IF(B27="","",MAX($B$3:B27)) | Y27: =IF(OR(B27="",X27=""),"",B27/X27-1) | Z27: =IF(D27="","",$B$3*D27/$D$3) | AA27: =IF(D27="","",D27/$D$3-1) | AB27: =IF(OR(W27="",AA27=""),"",W27-AA27) | AE27: =IF(AD27="","",AC27*AD27) | AF27: =IF(OR(AE27="",B27="",B27=0),"",AE27/B27) | AG27: -0.59
A28: 46273 | B28: =IF(AND(E28="",I28="",AE28="",AG28=""),"",SUM(E28,I28,AE28,AG28)) | C28: 79.076369 | D28: 718.36 | E28: =IF(D28="","",D28*C28) | F28: =IF(B28="","",E28/B28) | G28: 682.07247 | H28: 72.16 | I28: =IF(H28="","",H28*G28) | J28: =IF(B28="","",I28/B28) | K28: =IF(B28="","",F28+J28*3) | L28: 1.92x | M28: no change - hold current position | N28: 1.98x | O28: 0.9 | P28: 0.37 | Q28: 0.91 | R28: 0.28 | S28: 105 | T28: above | U28: No | V28: =IF(OR(B28="",B27=""),"",B28/B27-1) | W28: =IF(B28="","",B28/$B$3-1) | X28: =IF(B28="","",MAX($B$3:B28)) | Y28: =IF(OR(B28="",X28=""),"",B28/X28-1) | Z28: =IF(D28="","",$B$3*D28/$D$3) | AA28: =IF(D28="","",D28/$D$3-1) | AB28: =IF(OR(W28="",AA28=""),"",W28-AA28) | AE28: =IF(AD28="","",AC28*AD28) | AF28: =IF(OR(AE28="",B28="",B28=0),"",AE28/B28) | AG28: -0.59
A29: 46274 | B29: =IF(AND(E29="",I29="",AE29="",AG29=""),"",SUM(E29,I29,AE29,AG29)) | C29: 79.076369 | D29: 716.31 | E29: =IF(D29="","",D29*C29) | F29: =IF(B29="","",E29/B29) | G29: 682.07247 | H29: 71.55 | I29: =IF(H29="","",H29*G29) | J29: =IF(B29="","",I29/B29) | K29: =IF(B29="","",F29+J29*3) | L29: 1.92x | M29: no change - hold current position | N29: 1.99x | O29: 0.89 | P29: 0.39 | Q29: 0.91 | R29: 0.28 | S29: 106 | T29: above | U29: No | V29: =IF(OR(B29="",B28=""),"",B29/B28-1) | W29: =IF(B29="","",B29/$B$3-1) | X29: =IF(B29="","",MAX($B$3:B29)) | Y29: =IF(OR(B29="",X29=""),"",B29/X29-1) | Z29: =IF(D29="","",$B$3*D29/$D$3) | AA29: =IF(D29="","",D29/$D$3-1) | AB29: =IF(OR(W29="",AA29=""),"",W29-AA29) | AE29: =IF(AD29="","",AC29*AD29) | AF29: =IF(OR(AE29="",B29="",B29=0),"",AE29/B29) | AG29: -0.59
A30: 46275 | B30: =IF(AND(E30="",I30="",AE30="",AG30=""),"",SUM(E30,I30,AE30,AG30)) | C30: 79.076369 | D30: 708.69 | E30: =IF(D30="","",D30*C30) | F30: =IF(B30="","",E30/B30) | G30: 682.07247 | H30: 69.21 | I30: =IF(H30="","",H30*G30) | J30: =IF(B30="","",I30/B30) | K30: =IF(B30="","",F30+J30*3) | L30: 1.92x | M30: no change - hold current position | N30: 1.99x | O30: 0.89 | P30: 0.42 | Q30: 0.91 | R30: 0.28 | S30: 107 | T30: above | U30: No | V30: =IF(OR(B30="",B29=""),"",B30/B29-1) | W30: =IF(B30="","",B30/$B$3-1) | X30: =IF(B30="","",MAX($B$3:B30)) | Y30: =IF(OR(B30="",X30=""),"",B30/X30-1) | Z30: =IF(D30="","",$B$3*D30/$D$3) | AA30: =IF(D30="","",D30/$D$3-1) | AB30: =IF(OR(W30="",AA30=""),"",W30-AA30) | AE30: =IF(AD30="","",AC30*AD30) | AF30: =IF(OR(AE30="",B30="",B30=0),"",AE30/B30) | AG30: -0.59
A31: 46276 | B31: =IF(AND(E31="",I31="",AE31="",AG31=""),"",SUM(E31,I31,AE31,AG31)) | C31: 79.076369 | D31: 714.88 | E31: =IF(D31="","",D31*C31) | F31: =IF(B31="","",E31/B31) | G31: 682.07247 | H31: 70.98 | I31: =IF(H31="","",H31*G31) | J31: =IF(B31="","",I31/B31) | K31: =IF(B31="","",F31+J31*3) | L31: 1.92x | M31: no change - hold current position | N31: 1.94x | O31: 0.89 | P31: 0.39 | Q31: 0.91 | R31: 0.28 | S31: 108 | T31: above | U31: No | V31: =IF(OR(B31="",B30=""),"",B31/B30-1) | W31: =IF(B31="","",B31/$B$3-1) | X31: =IF(B31="","",MAX($B$3:B31)) | Y31: =IF(OR(B31="",X31=""),"",B31/X31-1) | Z31: =IF(D31="","",$B$3*D31/$D$3) | AA31: =IF(D31="","",D31/$D$3-1) | AB31: =IF(OR(W31="",AA31=""),"",W31-AA31) | AE31: =IF(AD31="","",AC31*AD31) | AF31: =IF(OR(AE31="",B31="",B31=0),"",AE31/B31) | AG31: -0.59
A32: 46279 | B32: =IF(AND(E32="",I32="",AE32="",AG32=""),"",SUM(E32,I32,AE32,AG32)) | C32: 79.076369 | D32: 709.18 | E32: =IF(D32="","",D32*C32) | F32: =IF(B32="","",E32/B32) | G32: 682.07247 | H32: 69.27 | I32: =IF(H32="","",H32*G32) | J32: =IF(B32="","",I32/B32) | K32: =IF(B32="","",F32+J32*3) | L32: 1.92x | M32: no change - hold current position | N32: 1.98x | O32: 0.89 | P32: 0.42 | Q32: 0.91 | R32: 0.28 | S32: 109 | T32: above | U32: No | V32: =IF(OR(B32="",B31=""),"",B32/B31-1) | W32: =IF(B32="","",B32/$B$3-1) | X32: =IF(B32="","",MAX($B$3:B32)) | Y32: =IF(OR(B32="",X32=""),"",B32/X32-1) | Z32: =IF(D32="","",$B$3*D32/$D$3) | AA32: =IF(D32="","",D32/$D$3-1) | AB32: =IF(OR(W32="",AA32=""),"",W32-AA32) | AE32: =IF(AD32="","",AC32*AD32) | AF32: =IF(OR(AE32="",B32="",B32=0),"",AE32/B32) | AG32: -0.59
A33: 46280 | B33: =IF(AND(E33="",I33="",AE33="",AG33=""),"",SUM(E33,I33,AE33,AG33)) | C33: 79.076369 | D33: 704.54 | E33: =IF(D33="","",D33*C33) | F33: =IF(B33="","",E33/B33) | G33: 682.07247 | H33: 67.9 | I33: =IF(H33="","",H33*G33) | J33: =IF(B33="","",I33/B33) | K33: =IF(B33="","",F33+J33*3) | L33: 1.92x | M33: no change - hold current position | N33: 1.93x | O33: 0.89 | P33: 0.44 | Q33: 0.91 | R33: 0.28 | S33: 110 | T33: above | U33: No | V33: =IF(OR(B33="",B32=""),"",B33/B32-1) | W33: =IF(B33="","",B33/$B$3-1) | X33: =IF(B33="","",MAX($B$3:B33)) | Y33: =IF(OR(B33="",X33=""),"",B33/X33-1) | Z33: =IF(D33="","",$B$3*D33/$D$3) | AA33: =IF(D33="","",D33/$D$3-1) | AB33: =IF(OR(W33="",AA33=""),"",W33-AA33) | AE33: =IF(AD33="","",AC33*AD33) | AF33: =IF(OR(AE33="",B33="",B33=0),"",AE33/B33) | AG33: -0.59
A34: 46281 | B34: =IF(AND(E34="",I34="",AE34="",AG34=""),"",SUM(E34,I34,AE34,AG34)) | C34: 79.076369 | D34: 704.72 | E34: =IF(D34="","",D34*C34) | F34: =IF(B34="","",E34/B34) | G34: 682.07247 | H34: 67.93 | I34: =IF(H34="","",H34*G34) | J34: =IF(B34="","",I34/B34) | K34: =IF(B34="","",F34+J34*3) | L34: 1.92x | M34: no change - hold current position | N34: 1.90x | O34: 0.89 | P34: 0.5 | Q34: 0.91 | R34: 0.28 | S34: 111 | T34: above | U34: No | V34: =IF(OR(B34="",B33=""),"",B34/B33-1) | W34: =IF(B34="","",B34/$B$3-1) | X34: =IF(B34="","",MAX($B$3:B34)) | Y34: =IF(OR(B34="",X34=""),"",B34/X34-1) | Z34: =IF(D34="","",$B$3*D34/$D$3) | AA34: =IF(D34="","",D34/$D$3-1) | AB34: =IF(OR(W34="",AA34=""),"",W34-AA34) | AE34: =IF(AD34="","",AC34*AD34) | AF34: =IF(OR(AE34="",B34="",B34=0),"",AE34/B34) | AG34: -0.59
A35: 46282 | B35: =IF(AND(E35="",I35="",AE35="",AG35=""),"",SUM(E35,I35,AE35,AG35)) | C35: 63.171766 | D35: 716.92 | E35: =IF(D35="","",D35*C35) | F35: =IF(B35="","",E35/B35) | G35: 842.76059 | H35: 71.38 | I35: =IF(H35="","",H35*G35) | J35: =IF(B35="","",I35/B35) | K35: =IF(B35="","",F35+J35*3) | L35: 2.13x | M35: REBALANCE — 54.04% QQQ / 45.96% TQQQ → 43.29% QQQ / 56.71% TQQQ | N35: 2.13x | O35: 0.89 | P35: 0.5 | Q35: 0.91 | R35: 0.28 | S35: 112 | T35: above | U35: No | V35: =IF(OR(B35="",B34=""),"",B35/B34-1) | W35: =IF(B35="","",B35/$B$3-1) | X35: =IF(B35="","",MAX($B$3:B35)) | Y35: =IF(OR(B35="",X35=""),"",B35/X35-1) | Z35: =IF(D35="","",$B$3*D35/$D$3) | AA35: =IF(D35="","",D35/$D$3-1) | AB35: =IF(OR(W35="",AA35=""),"",W35-AA35) | AE35: =IF(AD35="","",AC35*AD35) | AF35: =IF(OR(AE35="",B35="",B35=0),"",AE35/B35) | AG35: 0 | AH35: Y
A36: 46283 | B36: =IF(AND(E36="",I36="",AE36="",AG36=""),"",SUM(E36,I36,AE36,AG36)) | C36: 80.918218 | D36: 721.45 | E36: =IF(D36="","",D36*C36) | F36: =IF(B36="","",E36/B36) | G36: 665.39477 | H36: 72.64 | I36: =IF(H36="","",H36*G36) | J36: =IF(B36="","",I36/B36) | K36: =IF(B36="","",F36+J36*3) | L36: 1.90x | M36: REBALANCE — 43.29% QQQ / 56.71% TQQQ → 55.20% QQQ / 44.80% TQQQ | N36: 1.90x | O36: 0.89 | P36: 0.46 | Q36: 0.91 | R36: 0.28 | S36: 113 | T36: above | U36: No | V36: =IF(OR(B36="",B35=""),"",B36/B35-1) | W36: =IF(B36="","",B36/$B$3-1) | X36: =IF(B36="","",MAX($B$3:B36)) | Y36: =IF(OR(B36="",X36=""),"",B36/X36-1) | Z36: =IF(D36="","",$B$3*D36/$D$3) | AA36: =IF(D36="","",D36/$D$3-1) | AB36: =IF(OR(W36="",AA36=""),"",W36-AA36) | AE36: =IF(AD36="","",AC36*AD36) | AF36: =IF(OR(AE36="",B36="",B36=0),"",AE36/B36) | AG36: 0 | AH36: Y
A37: 46286 | B37: =IF(AND(E37="",I37="",AE37="",AG37=""),"",SUM(E37,I37,AE37,AG37)) | C37: 80.918218 | D37: 741.47 | E37: =IF(D37="","",D37*C37) | F37: =IF(B37="","",E37/B37) | G37: 665.39477 | H37: 78.91 | I37: =IF(H37="","",H37*G37) | J37: =IF(B37="","",I37/B37) | K37: =IF(B37="","",F37+J37*3) | L37: 1.90x | M37: no change - hold current position | N37: 1.90x | O37: 0.89 | P37: 0.49 | Q37: 0.91 | R37: 0.28 | S37: 114 | T37: above | U37: No | V37: =IF(OR(B37="",B36=""),"",B37/B36-1) | W37: =IF(B37="","",B37/$B$3-1) | X37: =IF(B37="","",MAX($B$3:B37)) | Y37: =IF(OR(B37="",X37=""),"",B37/X37-1) | Z37: =IF(D37="","",$B$3*D37/$D$3) | AA37: =IF(D37="","",D37/$D$3-1) | AB37: =IF(OR(W37="",AA37=""),"",W37-AA37) | AE37: =IF(AD37="","",AC37*AD37) | AF37: =IF(OR(AE37="",B37="",B37=0),"",AE37/B37) | AG37: 0
A38: 46287 | B38: =IF(AND(E38="",I38="",AE38="",AG38=""),"",SUM(E38,I38,AE38,AG38)) | C38: 112.0874 | D38: 747.46 | E38: =IF(D38="","",D38*C38) | F38: =IF(B38="","",E38/B38) | G38: 374.58401 | H38: 80.83 | I38: =IF(H38="","",H38*G38) | J38: =IF(B38="","",I38/B38) | K38: =IF(B38="","",F38+J38*3) | L38: 1.52x | M38: REBALANCE — 55.20% QQQ / 44.80% TQQQ → 73.85% QQQ / 26.15% TQQQ | N38: 1.52x | O38: 0.89 | P38: 0.45 | Q38: 0.91 | R38: 0.28 | S38: 115 | T38: above | U38: No | V38: =IF(OR(B38="",B37=""),"",B38/B37-1) | W38: =IF(B38="","",B38/$B$3-1) | X38: =IF(B38="","",MAX($B$3:B38)) | Y38: =IF(OR(B38="",X38=""),"",B38/X38-1) | Z38: =IF(D38="","",$B$3*D38/$D$3) | AA38: =IF(D38="","",D38/$D$3-1) | AB38: =IF(OR(W38="",AA38=""),"",W38-AA38) | AE38: =IF(AD38="","",AC38*AD38) | AF38: =IF(OR(AE38="",B38="",B38=0),"",AE38/B38) | AG38: 0 | AH38: Y
A39: 46288 | B39: =IF(AND(E39="",I39="",AE39="",AG39=""),"",SUM(E39,I39,AE39,AG39)) | C39: 112.0874 | D39: 741.21 | E39: =IF(D39="","",D39*C39) | F39: =IF(B39="","",E39/B39) | G39: 374.58401 | H39: 78.66 | I39: =IF(H39="","",H39*G39) | J39: =IF(B39="","",I39/B39) | K39: =IF(B39="","",F39+J39*3) | L39: 1.52x | M39: no change - hold current position | N39: 1.53x | O39: 0.89 | P39: 0.42 | Q39: 0.91 | R39: 0.28 | S39: 116 | T39: above | U39: No | V39: =IF(OR(B39="",B38=""),"",B39/B38-1) | W39: =IF(B39="","",B39/$B$3-1) | X39: =IF(B39="","",MAX($B$3:B39)) | Y39: =IF(OR(B39="",X39=""),"",B39/X39-1) | Z39: =IF(D39="","",$B$3*D39/$D$3) | AA39: =IF(D39="","",D39/$D$3-1) | AB39: =IF(OR(W39="",AA39=""),"",W39-AA39) | AE39: =IF(AD39="","",AC39*AD39) | AF39: =IF(OR(AE39="",B39="",B39=0),"",AE39/B39) | AG39: 0
A40: 46289 | B40: =IF(AND(E40="",I40="",AE40="",AG40=""),"",SUM(E40,I40,AE40,AG40)) | C40: 112.0874 | D40: 741.1 | E40: =IF(D40="","",D40*C40) | F40: =IF(B40="","",E40/B40) | G40: 374.58401 | H40: 78.58 | I40: =IF(H40="","",H40*G40) | J40: =IF(B40="","",I40/B40) | K40: =IF(B40="","",F40+J40*3) | L40: 1.52x | M40: no change - hold current position | N40: 1.52x | O40: 0.89 | P40: 0.43 | Q40: 0.91 | R40: 0.28 | S40: 117 | T40: above | U40: No | V40: =IF(OR(B40="",B39=""),"",B40/B39-1) | W40: =IF(B40="","",B40/$B$3-1) | X40: =IF(B40="","",MAX($B$3:B40)) | Y40: =IF(OR(B40="",X40=""),"",B40/X40-1) | Z40: =IF(D40="","",$B$3*D40/$D$3) | AA40: =IF(D40="","",D40/$D$3-1) | AB40: =IF(OR(W40="",AA40=""),"",W40-AA40) | AE40: =IF(AD40="","",AC40*AD40) | AF40: =IF(OR(AE40="",B40="",B40=0),"",AE40/B40) | AG40: 0
...

Sheet Trade Log
A1: Trade Log — one row per executed (paper) trade | H1: =SUM(H4:H1000)
A2: Slippage auto-computes in bps vs the ARRIVAL price (NBBO midpoint when the order was sent; the official open for orders sent before the open), signed so POSITIVE = adverse. It measures execution only, not the day's market move.
A3: Date | B3: Symbol | C3: Side (buy/sell) | D3: Shares | E3: Notional $ | F3: Arrival price (NBBO mid at order) | G3: Fill price | H3: Slippage (bps, adverse+) | I3: Notes
A4: 46230 | B4: QQQ | C4: buy | D4: 146.89422 | E4: =IF(OR(D4="",G4=""),"",D4*G4) | G4: 680.7619 | H4: =IF(OR(F4="",G4="",C4=""),"",(G4-F4)/F4*10000*IF(LOWER(C4)="buy",1,-1)) | I4: Pre-v3.3: account opened under v3.1. Starting position for the 8/3 record; intended price left blank so it stays out of v3.3 slippage stats.
A5: 46252 | B5: QQQ | C5: sell | D5: 3.9143181 | E5: =IF(OR(D5="",G5=""),"",D5*G5) | F5: 720.21 | G5: 720.41788 | H5: =IF(OR(F5="",G5="",C5=""),"",(G5-F5)/F5*10000*IF(LOWER(C5)="buy",1,-1)) | I5: First TQQQ rebalance (was missing; from Alpaca)
A6: 46252 | B6: TQQQ | C6: buy | D6: 37.394546 | E6: =IF(OR(D6="",G6=""),"",D6*G6) | F6: 73.36 | G6: 73.372914 | H6: =IF(OR(F6="",G6="",C6=""),"",(G6-F6)/F6*10000*IF(LOWER(C6)="buy",1,-1)) | I6: First TQQQ rebalance (was missing; from Alpaca)
A7: 46259 | B7: QQQ | C7: sell | D7: 18.841315 | E7: =IF(OR(D7="",G7=""),"",D7*G7) | F7: 710.095 | G7: 710.15319 | H7: =IF(OR(F7="",G7="",C7=""),"",(G7-F7)/F7*10000*IF(LOWER(C7)="buy",1,-1)) | I7: Bug
A8: 46259 | B8: TQQQ | C8: buy | D8: 191.89601 | E8: =IF(OR(D8="",G8=""),"",D8*G8) | F8: 70.105 | G8: 70.123033 | H8: =IF(OR(F8="",G8="",C8=""),"",(G8-F8)/F8*10000*IF(LOWER(C8)="buy",1,-1)) | I8: Bug
A9: 46260 | B9: TQQQ | C9: sell | D9: 193.6037 | E9: =IF(OR(D9="",G9=""),"",D9*G9) | F9: 70.235 | G9: 70.223038 | H9: =IF(OR(F9="",G9="",C9=""),"",(G9-F9)/F9*10000*IF(LOWER(C9)="buy",1,-1)) | I9: Fixed Bug
A10: 46260 | B10: QQQ | C10: buy | D10: 19.131587 | E10: =IF(OR(D10="",G10=""),"",D10*G10) | F10: 710.675 | G10: 710.62791 | H10: =IF(OR(F10="",G10="",C10=""),"",(G10-F10)/F10*10000*IF(LOWER(C10)="buy",1,-1)) | I10: Fixed Bug
A11: 46261 | B11: QQQ | C11: sell | D11: 11.241575 | E11: =IF(OR(D11="",G11=""),"",D11*G11) | F11: 717.77 | G11: 716.63 | H11: =IF(OR(F11="",G11="",C11=""),"",(G11-F11)/F11*10000*IF(LOWER(C11)="buy",1,-1)) | I11: Real Trade
A12: 46261 | B12: TQQQ | C12: buy | D12: 112.14785 | E12: =IF(OR(D12="",G12=""),"",D12*G12) | F12: 72.33 | G12: 71.831513 | H12: =IF(OR(F12="",G12="",C12=""),"",(G12-F12)/F12*10000*IF(LOWER(C12)="buy",1,-1)) | I12: Real Trade
A13: 46262 | B13: QQQ | C13: sell | D13: 14.200145 | E13: =IF(OR(D13="",G13=""),"",D13*G13) | F13: 718.82 | G13: 718.80254 | H13: =IF(OR(F13="",G13="",C13=""),"",(G13-F13)/F13*10000*IF(LOWER(C13)="buy",1,-1)) | I13: Real Trade
A14: 46262 | B14: TQQQ | C14: buy | D14: 140.86061 | E14: =IF(OR(D14="",G14=""),"",D14*G14) | F14: 72.575 | G14: 72.46 | H14: =IF(OR(F14="",G14="",C14=""),"",(G14-F14)/F14*10000*IF(LOWER(C14)="buy",1,-1)) | I14: Real Trade
A15: 46268 | B15: QQQ | C15: sell | D15: 38.752088 | E15: =IF(OR(D15="",G15=""),"",D15*G15) | F15: 711.23 | G15: 710.95317 | H15: =IF(OR(F15="",G15="",C15=""),"",(G15-F15)/F15*10000*IF(LOWER(C15)="buy",1,-1)) | I15: Real Trade
A16: 46268 | B16: TQQQ | C16: buy | D16: 393.37715 | E16: =IF(OR(D16="",G16=""),"",D16*G16) | F16: 70.165 | G16: 70.035816 | H16: =IF(OR(F16="",G16="",C16=""),"",(G16-F16)/F16*10000*IF(LOWER(C16)="buy",1,-1)) | I16: Real Trade
... A24: 46296 | B24: TQQQ | C24: buy | D24: 76.033224 | E24: =IF(OR(D24="",G24=""),"",D24*G24) | F24: 78.805 | G24: 78.952722 | H24: =IF(OR(F24="",G24="",C24=""),"",(G24-F24)/F24*10000*IF(LOWER(C24)="buy",1,-1)) | I24: Real Trade
E25: =IF(OR(D25="",G25=""),"",D25*G25) | H25: =IF(OR(F25="",G25="",C25=""),"",(G25-F25)/F25*10000*IF(LOWER(C25)="buy",1,-1))
E26: =IF(OR(D26="",G26=""),"",D26*G26) | H26: =IF(OR(F26="",G26="",C26=""),"",(G26-F26)/F26*10000*IF(LOWER(C26)="buy",1,-1))
E27: =IF(OR(D27="",G27=""),"",D27*G27) | H27: =IF(OR(F27="",G27="",C27=""),"",(G27-F27)/F27*10000*IF(LOWER(C27)="buy",1,-1))
E28: =IF(OR(D28="",G28=""),"",D28*G28) | H28: =IF(OR(F28="",G28="",C28=""),"",(G28-F28)/F28*10000*IF(LOWER(C28)="buy",1,-1))
E29: =IF(OR(D29="",G29=""),"",D29*G29) | H29: =IF(OR(F29="",G29="",C29=""),"",(G29-F29)/F29*10000*IF(LOWER(C29)="buy",1,-1))
E30: =IF(OR(D30="",G30=""),"",D30*G30) | H30: =IF(OR(F30="",G30="",C30=""),"",(G30-F30)/F30*10000*IF(LOWER(C30)="buy",1,-1))
E31: =IF(OR(D31="",G31=""),"",D31*G31) | H31: =IF(OR(F31="",G31="",C31=""),"",(G31-F31)/F31*10000*IF(LOWER(C31)="buy",1,-1))
E32: =IF(OR(D32="",G32=""),"",D32*G32) | H32: =IF(OR(F32="",G32="",C32=""),"",(G32-F32)/F32*10000*IF(LOWER(C32)="buy",1,-1))
E33: =IF(OR(D33="",G33=""),"",D33*G33) | H33: =IF(OR(F33="",G33="",C33=""),"",(G33-F33)/F33*10000*IF(LOWER(C33)="buy",1,-1))
E34: =IF(OR(D34="",G34=""),"",D34*G34) | H34: =IF(OR(F34="",G34="",C34=""),"",(G34-F34)/F34*10000*IF(LOWER(C34)="buy",1,-1))
E35: =IF(OR(D35="",G35=""),"",D35*G35) | H35: =IF(OR(F35="",G35="",C35=""),"",(G35-F35)/F35*10000*IF(LOWER(C35)="buy",1,-1))
E36: =IF(OR(D36="",G36=""),"",D36*G36) | H36: =IF(OR(F36="",G36="",C36=""),"",(G36-F36)/F36*10000*IF(LOWER(C36)="buy",1,-1))
... E44: =IF(OR(D44="",G44=""),"",D44*G44) | H44: =IF(OR(F44="",G44="",C44=""),"",(G44-F44)/F44*10000*IF(LOWER(C44)="buy",1,-1))
